<mujoco>
    <!-- Default settings for different tags of the model. -->
    <default>
        <joint pos="0 0 0" armature="1" limited="true" damping="1000" />
        <geom pos="0 0 0" rgba=".4 .4 .4 1" condim="3" contype="0" conaffinity="0" />
        <motor ctrlrange="-1 1" ctrllimited="true" gear="500" />
    </default>

    <compiler inertiafromgeom="true" angle="radian" />
    <option gravity="0 0 -2" timestep="0.01"/>

    <!-- Definition of all geometric shapes and joints. -->
    <worldbody>
        <!-- Diffuse lighting at position (0,0,3) pointing downwards in z direction. -->
        <light diffuse=".5 .5 .5" pos="0 0 10" dir="0 0 -1" castshadow="false" />
        
        <!-- Plane centered at origin with color green and size 1*1 unit^2. -->
        <geom name="table" type="plane" size="1.2 1.2 0.1" rgba="0 0.9 0 1" friction="0 0 0" contype="1" conaffinity="1" />

        <!-- Build walls around the plane. -->
        <geom type="box" size="1.2 0.02 0.2" pos="0 1.2 0.1" rgba="0 0 0.9 0.5"  contype="1" conaffinity="1" />
        <geom type="box" size="1.2 0.02 0.2" pos="0 -1.2 0.1" rgba="0 0 0.9 0.5"  contype="1" conaffinity="1" /> 
        <geom type="box" size="0.02 1.2 0.2" pos="1.2 0 0.1" rgba="0 0 0.9 0.5"  contype="1" conaffinity="1" />
        <geom type="box" size="0.02 1.2 0.2" pos="-1.2 0 0.1" rgba="0 0 0.9 0.5"  contype="1" conaffinity="1" />

        <!-- Build robotic arms. -->
        <body name="robot" pos="0 0 1.12">
            <joint name="cart_slide_x" type="slide" axis="1 0 0" range="-1 1" />
            <joint name="cart_slide_y" type="slide" axis="0 1 0" range="-1 1" />
            <joint name="cart_slide_z" type="slide" axis="0 0 1" range="0 0.3" />
            <joint name="cart_rotate_z" type="hinge" axis="0 0 1" range="-31.4 31.4" />

            <geom name="arm" type="box" size=".1 .05 .75" pos="0 0 0.1" />
            <geom name="wrist" type="box" size=".11 .06 .025" pos="0 0 -0.675" rgba=".9 .9 .9 1" contype="1" conaffinity="1" />

            <body name="round_hand" pos="0 0 -0.9">
                <geom name="hand" type="cylinder" size=".03 .2" density="0.002" contype="1" conaffinity="1" />
            </body>
        </body>

        <!-- Objects for the robot to push and goals for the objects. -->
        <body name="obj" pos="0 0 0.04">
            <geom type="sphere" size=".08" rgba=".8 .4 .6 1" density='0.00001' contype="1" conaffinity="1" />
            <joint name="obj_slide_z" type="slide" axis="0 0 1" range="-10 10" damping="10.0" />
            <joint name="obj_slide_x" type="slide" axis="1 0 0" range="-10 10" damping="10.0" />
            <joint name="obj_slide_y" type="slide" axis="0 1 0" range="-10 10" damping="10.0" />
        </body>

        <body name="goal1" pos="0 0 0">
            <geom type="cylinder" size="0.08 0.001" rgba="1 1 1 0" density='0.00001' contype="0" conaffinity="0" />
            <joint name="goal1_slide_x" type="slide" axis="1 0 0" range="-10 10" damping="0.5" />
            <joint name="goal1_slide_y" type="slide" axis="0 1 0" range="-10 10" damping="0.5" />
        </body>

        <body name="goal2" pos="0 0 0">
            <geom type="cylinder" size="0.08 0.001" rgba="1 1 1 0" density='0.00001' contype="0" conaffinity="0" />
            <joint name="goal2_slide_x" type="slide" axis="1 0 0" range="-10 10" damping="0.5" />
            <joint name="goal2_slide_y" type="slide" axis="0 1 0" range="-10 10" damping="0.5" />
        </body>

        <body name="goal3" pos="0 0 0">
            <geom type="cylinder" size="0.08 0.001" rgba="1 1 1 0" density='0.00001' contype="0" conaffinity="0" />
            <joint name="goal3_slide_x" type="slide" axis="1 0 0" range="-10 10" damping="0.5" />
            <joint name="goal3_slide_y" type="slide" axis="0 1 0" range="-10 10" damping="0.5" />
        </body>

        <!-- Obstacle -->
        <body name="obstacle" pos="0 0 0">
            <geom type="box" size=".01 .01 .01" pos="0 0 0" rgba="0 0 0 0" density="0.2" contype="0" conaffinity="0" />
            <joint name="obstacle_slide_x" type="slide" axis="1 0 0" range="-10 10" damping="0.5" />
            <joint name="obstacle_slide_y" type="slide" axis="0 1 0" range="-10 10" damping="0.5" />
            <body pos="0 0 0">
                <joint name="obstacle_rotate_z" type="hinge" axis="0 0 1" range="-31.4 31.4" />
                <geom type="box" size="0.4 0.02 0.2" pos="0 0 0" rgba="0 0 0.9 0.5" density="2147483647" contype="1" conaffinity="1" />
            </body>
        </body>
    </worldbody>

    <!-- Actuators that can be controlled by action vector. -->
    <actuator>
        <motor joint="cart_slide_x" />
        <motor joint="cart_slide_y" />
        <motor joint="cart_slide_z" />
        <motor joint="cart_rotate_z" gear="1000" />
    </actuator>
</mujoco>
