<mujoco>
    <default>
        <joint pos="0 0 0" armature="0" limited="true" damping="0.1" />
        <geom pos="0 0 0" rgba="1 1 1 1" contype="1" conaffinity="1" />
        <motor ctrlrange="-1 1" ctrllimited="true" gear="5" />
    </default>

    <worldbody>
        <light diffuse=".5 .5 .5" pos="0 0 10" dir="0 0 -1" /> 

        <geom type="plane" size="1 1 1" rgba="0 0.9 0 1" />

        <geom type="box" size="1 0.02 0.2" pos="0 1 0.1" rgba="0 0 0.9 0.5" />
        <geom type="box" size="1 0.02 0.2" pos="0 -1 0.1" rgba="0 0 0.9 0.5" />
        <geom type="box" size="0.02 1 0.2" pos="1 0 0.1" rgba="0 0 0.9 0.5" />
        <geom type="box" size="0.02 1 0.2" pos="-1 0 0.1" rgba="0 0 0.9 0.5" />

        <body name="ball" pos="0 0 0.1">
            <geom type="sphere" size="0.05" rgba=".9 .9 0 1" density='0.00001' />
            <joint name="ball_slide_x" type="slide" axis="1 0 0" range="-10 10" damping="0.5" />
            <joint name="ball_slide_y" type="slide" axis="0 1 0" range="-10 10" damping="0.5" />
        </body>

        <body name="goal" pos="0 0 0.1">
            <geom type="box" size="0.05 0.05 0.05" rgba="1 1 1 0.3" density='0.00001' contype="0" conaffinity="0" />
            <joint name="goal_slide_x" type="slide" axis="1 0 0" range="-10 10" damping="0.5" />
            <joint name="goal_slide_y" type="slide" axis="0 1 0" range="-10 10" damping="0.5" />
        </body>
	</worldbody>

	<actuator>
    	<motor joint="ball_slide_x" />
    	<motor joint="ball_slide_y" />
	</actuator>
</mujoco>
